{
 "cells": [
  {
   "cell_type": "code",
   "execution_count": 6,
   "metadata": {},
   "outputs": [],
   "source": [
    "import numpy, random, math"
   ]
  },
  {
   "cell_type": "code",
   "execution_count": 5,
   "metadata": {
    "collapsed": true
   },
   "outputs": [],
   "source": [
    "from scipy.optimize import minimize"
   ]
  },
  {
   "cell_type": "code",
   "execution_count": 10,
   "metadata": {},
   "outputs": [
    {
     "name": "stderr",
     "output_type": "stream",
     "text": [
      "ERROR:root:Internal Python error in the inspect module.\n",
      "Below is the traceback from this internal error.\n",
      "\n"
     ]
    },
    {
     "name": "stdout",
     "output_type": "stream",
     "text": [
      "Traceback (most recent call last):\n",
      "  File \"/Users/Hiidenheimo/anaconda3/lib/python3.6/site-packages/IPython/core/interactiveshell.py\", line 2862, in run_code\n",
      "    exec(code_obj, self.user_global_ns, self.user_ns)\n",
      "  File \"<ipython-input-10-eff513f636fd>\", line 1, in <module>\n",
      "    import matplotlib.pyplot as plt\n",
      "  File \"/Users/Hiidenheimo/anaconda3/lib/python3.6/site-packages/matplotlib/__init__.py\", line 1060, in <module>\n",
      "    rcParams = rc_params()\n",
      "  File \"/Users/Hiidenheimo/anaconda3/lib/python3.6/site-packages/matplotlib/__init__.py\", line 892, in rc_params\n",
      "    fname = matplotlib_fname()\n",
      "  File \"/Users/Hiidenheimo/anaconda3/lib/python3.6/site-packages/matplotlib/__init__.py\", line 736, in matplotlib_fname\n",
      "    for fname in gen_candidates():\n",
      "  File \"/Users/Hiidenheimo/anaconda3/lib/python3.6/site-packages/matplotlib/__init__.py\", line 725, in gen_candidates\n",
      "    yield os.path.join(six.moves.getcwd(), 'matplotlibrc')\n",
      "FileNotFoundError: [Errno 2] No such file or directory\n",
      "\n",
      "During handling of the above exception, another exception occurred:\n",
      "\n",
      "Traceback (most recent call last):\n",
      "  File \"/Users/Hiidenheimo/anaconda3/lib/python3.6/site-packages/IPython/core/interactiveshell.py\", line 1806, in showtraceback\n",
      "    stb = value._render_traceback_()\n",
      "AttributeError: 'FileNotFoundError' object has no attribute '_render_traceback_'\n",
      "\n",
      "During handling of the above exception, another exception occurred:\n",
      "\n",
      "Traceback (most recent call last):\n",
      "  File \"/Users/Hiidenheimo/anaconda3/lib/python3.6/site-packages/IPython/core/ultratb.py\", line 1090, in get_records\n",
      "    return _fixed_getinnerframes(etb, number_of_lines_of_context, tb_offset)\n",
      "  File \"/Users/Hiidenheimo/anaconda3/lib/python3.6/site-packages/IPython/core/ultratb.py\", line 311, in wrapped\n",
      "    return f(*args, **kwargs)\n",
      "  File \"/Users/Hiidenheimo/anaconda3/lib/python3.6/site-packages/IPython/core/ultratb.py\", line 345, in _fixed_getinnerframes\n",
      "    records = fix_frame_records_filenames(inspect.getinnerframes(etb, context))\n",
      "  File \"/Users/Hiidenheimo/anaconda3/lib/python3.6/inspect.py\", line 1480, in getinnerframes\n",
      "    frameinfo = (tb.tb_frame,) + getframeinfo(tb, context)\n",
      "  File \"/Users/Hiidenheimo/anaconda3/lib/python3.6/inspect.py\", line 1438, in getframeinfo\n",
      "    filename = getsourcefile(frame) or getfile(frame)\n",
      "  File \"/Users/Hiidenheimo/anaconda3/lib/python3.6/inspect.py\", line 693, in getsourcefile\n",
      "    if getattr(getmodule(object, filename), '__loader__', None) is not None:\n",
      "  File \"/Users/Hiidenheimo/anaconda3/lib/python3.6/inspect.py\", line 722, in getmodule\n",
      "    file = getabsfile(object, _filename)\n",
      "  File \"/Users/Hiidenheimo/anaconda3/lib/python3.6/inspect.py\", line 706, in getabsfile\n",
      "    return os.path.normcase(os.path.abspath(_filename))\n",
      "  File \"/Users/Hiidenheimo/anaconda3/lib/python3.6/posixpath.py\", line 374, in abspath\n",
      "    cwd = os.getcwd()\n",
      "FileNotFoundError: [Errno 2] No such file or directory\n"
     ]
    },
    {
     "ename": "FileNotFoundError",
     "evalue": "[Errno 2] No such file or directory",
     "output_type": "error",
     "traceback": [
      "\u001b[0;31m---------------------------------------------------------------------------\u001b[0m"
     ]
    }
   ],
   "source": [
    "import matplotlib.pyplot as plt"
   ]
  },
  {
   "cell_type": "code",
   "execution_count": null,
   "metadata": {
    "collapsed": true
   },
   "outputs": [],
   "source": []
  }
 ],
 "metadata": {
  "kernelspec": {
   "display_name": "Python 3",
   "language": "python",
   "name": "python3"
  },
  "language_info": {
   "codemirror_mode": {
    "name": "ipython",
    "version": 3
   },
   "file_extension": ".py",
   "mimetype": "text/x-python",
   "name": "python",
   "nbconvert_exporter": "python",
   "pygments_lexer": "ipython3",
   "version": "3.6.3"
  }
 },
 "nbformat": 4,
 "nbformat_minor": 2
}
